Everything worked almost as expected, but I received strange "Unhandled exception" in create user endpoint ->

// authorized call to User/Create endpoint with attached data does not work -> 
/*

RESPONSE:

{
  "success": false,
  "data": {
    "error": {
      "code": "UnhandledException",
      "message": "Error creating user."
    }
  },
  "message": {
    "text": "Error creating user.",
    "type": 3
  }
}

REQUEST:

curl -X 'POST' \
  'https://pimb2bqatesting-api.dev01.pimalion.cloud/app/User/Create' \
  -H 'accept: text/plain' \
  -H 'Authorization: Bearer eyJhbGciOiJIUzI1NiIsInR5cCI6IkpXVCJ9.eyJzdWIiOiJwcmFjdGljYWxUZXN0QGdtYWlsLmNvbSIsImh0dHA6Ly9zY2hlbWFzLnhtbHNvYXAub3JnL3dzLzIwMDUvMDUvaWRlbnRpdHkvY2xhaW1zL25hbWUiOiJwcmFjdGljYWxUZXN0QGdtYWlsLmNvbSIsImh0dHA6Ly9zY2hlbWFzLnhtbHNvYXAub3JnL3dzLzIwMDUvMDUvaWRlbnRpdHkvY2xhaW1zL3NpZCI6IjY0OTFiMGRhMWU2ZTc2ZjJiMjdjNTk4YSIsImh0dHA6Ly9zY2hlbWFzLm1pY3Jvc29mdC5jb20vd3MvMjAwOC8wNi9pZGVudGl0eS9jbGFpbXMvcm9sZSI6IlByYWN0aWNhbFRlc3QiLCJEZXBhcnRtZW50SWQiOiI1Y2M3NzkwYzRmM2E1MTZjNDFjNDkzZDAiLCJJc3N1ZWRBdCI6IjYzODM0NjM5MDkwMDYxMjY3MyIsIkxhYmVsQ29kZXMiOiJCQUwsQ0lGLFNBTCIsImV4cCI6MTY5OTA0Mjg5MCwiaXNzIjoiUGltYWxpb24uUHVibGlzaGluZy5BUEkiLCJhdWQiOiJQaW1hbGlvbi5QdWJsaXNoaW5nLkFQSSJ9.LVBGQ-ELxo_KQ1oaWi_AGels1d8lb9-DZogjb4mJ9FY' \
  -H 'Content-Type: application/json-patch+json' \
  -d '{
  "user": {
    "id": "6491b0da1e6e76f2b27c598a",
    "firstName": "test1",
    "lastName": "test1",
    "email": "jan@jan.com",
    "userName": "trefdsfdsfds",
    "active": true,
    "apiAccessAllowed": true,
    "roles": [
      {
        "name": "PracticalTest"
      }
    ],
    "labels": [
      {
        "id": "5fcf87651c32f90ce8dbcfb9",
        "name": "Balitrand"
      }
    ],
    "userPreferences": [
    ],
    "password": "Test123456",
    "departmentId": "5cc7790c4f3a516c41c493d0",
    "notify": true,
    "language": {
      "id": "5ca493950d7cac452d10c22a",
      "name": "fr-FR"
    },
    "enabled": true,
    "tokenExpiration": 0
  }
}'

*/